encoder1.0.weight 7200
encoder1.0.bias 150
encoder1.2.weight 12000
encoder1.2.bias 80
encoder1.4.weight 2400
encoder1.4.bias 30
decoder1.0.weight 2400
decoder1.0.bias 80
decoder1.2.weight 12000
decoder1.2.bias 150
decoder1.4.weight 7200
decoder1.4.bias 48
Total Trainable Params: 43738
Val loss: 3934.211590576172	 Val error: 188842.1578125
Epoch - 0	 step - 158 	Train loss - 2209.688355259925 	 MAE - 2209.688353042016
Val loss: 1695.8047790527344	 Val error: 81398.62918379935
Epoch - 1	 step - 158 	Train loss - 1441.7999114030563 	 MAE - 1441.7999109765353
Traceback (most recent call last):
  File "train.py", line 70, in <module>
    train_dataset = DatasetReader1(file_path = "AE1_out.csv", mode ='train',num = cfg.ae2_input)
  File "/home/atharva1511/Downloads/CS6910/assignment2/task2/dataloader.py", line 16, in __init__
    X = pd.read_csv(file_path, usecols = self.cols)
  File "/home/atharva1511/.local/lib/python3.8/site-packages/pandas/util/_decorators.py", line 311, in wrapper
    return func(*args, **kwargs)
  File "/home/atharva1511/.local/lib/python3.8/site-packages/pandas/io/parsers/readers.py", line 680, in read_csv
    return _read(filepath_or_buffer, kwds)
  File "/home/atharva1511/.local/lib/python3.8/site-packages/pandas/io/parsers/readers.py", line 575, in _read
    parser = TextFileReader(filepath_or_buffer, **kwds)
  File "/home/atharva1511/.local/lib/python3.8/site-packages/pandas/io/parsers/readers.py", line 933, in __init__
    self._engine = self._make_engine(f, self.engine)
  File "/home/atharva1511/.local/lib/python3.8/site-packages/pandas/io/parsers/readers.py", line 1231, in _make_engine
    return mapping[engine](f, **self.options)
  File "/home/atharva1511/.local/lib/python3.8/site-packages/pandas/io/parsers/c_parser_wrapper.py", line 131, in __init__
    self._validate_usecols_names(usecols, self.orig_names)
  File "/home/atharva1511/.local/lib/python3.8/site-packages/pandas/io/parsers/base_parser.py", line 913, in _validate_usecols_names
    raise ValueError(
ValueError: Usecols do not match columns, columns expected but not found: ['x31', 'x30', 'x33', 'x32', 'x34']
Traceback (most recent call last):
  File "train.py", line 70, in <module>
    train_dataset = DatasetReader1(file_path = "AE1_out.csv", mode ='train',num = cfg.ae2_input)
  File "/home/atharva1511/Downloads/CS6910/assignment2/task2/dataloader.py", line 16, in __init__
    X = pd.read_csv(file_path, usecols = self.cols)
  File "/home/atharva1511/.local/lib/python3.8/site-packages/pandas/util/_decorators.py", line 311, in wrapper
    return func(*args, **kwargs)
  File "/home/atharva1511/.local/lib/python3.8/site-packages/pandas/io/parsers/readers.py", line 680, in read_csv
    return _read(filepath_or_buffer, kwds)
  File "/home/atharva1511/.local/lib/python3.8/site-packages/pandas/io/parsers/readers.py", line 575, in _read
    parser = TextFileReader(filepath_or_buffer, **kwds)
  File "/home/atharva1511/.local/lib/python3.8/site-packages/pandas/io/parsers/readers.py", line 933, in __init__
    self._engine = self._make_engine(f, self.engine)
  File "/home/atharva1511/.local/lib/python3.8/site-packages/pandas/io/parsers/readers.py", line 1231, in _make_engine
    return mapping[engine](f, **self.options)
  File "/home/atharva1511/.local/lib/python3.8/site-packages/pandas/io/parsers/c_parser_wrapper.py", line 131, in __init__
    self._validate_usecols_names(usecols, self.orig_names)
  File "/home/atharva1511/.local/lib/python3.8/site-packages/pandas/io/parsers/base_parser.py", line 913, in _validate_usecols_names
    raise ValueError(
ValueError: Usecols do not match columns, columns expected but not found: ['x31', 'x30', 'x33', 'x32', 'x34']