2022-03-15 21:30:43,382 INFO    MainThread:10218 [internal.py:wandb_internal():92] W&B internal server running at pid: 10218, started at: 2022-03-15 21:30:43.382303
2022-03-15 21:30:43,384 INFO    WriterThread:10218 [datastore.py:open_for_write():77] open: /home/atharva1511/Downloads/CS6910/CS6910/code2/wandb/run-20220315_213042-3jrc9ezd/run-3jrc9ezd.wandb
2022-03-15 21:30:43,385 DEBUG   SenderThread:10218 [sender.py:send():235] send: header
2022-03-15 21:30:43,385 DEBUG   SenderThread:10218 [sender.py:send():235] send: run
2022-03-15 21:30:46,848 ERROR   SenderThread:10218 [retry.py:__call__():126] Retry attempt failed:
Traceback (most recent call last):
  File "/usr/lib/python3/dist-packages/urllib3/connection.py", line 159, in _new_conn
    conn = connection.create_connection(
  File "/usr/lib/python3/dist-packages/urllib3/util/connection.py", line 61, in create_connection
    for res in socket.getaddrinfo(host, port, family, socket.SOCK_STREAM):
  File "/usr/lib/python3.8/socket.py", line 918, in getaddrinfo
    for res in _socket.getaddrinfo(host, port, family, type, proto, flags):
socket.gaierror: [Errno -3] Temporary failure in name resolution

During handling of the above exception, another exception occurred:

Traceback (most recent call last):
  File "/usr/lib/python3/dist-packages/urllib3/connectionpool.py", line 665, in urlopen
    httplib_response = self._make_request(
  File "/usr/lib/python3/dist-packages/urllib3/connectionpool.py", line 376, in _make_request
    self._validate_conn(conn)
  File "/usr/lib/python3/dist-packages/urllib3/connectionpool.py", line 996, in _validate_conn
    conn.connect()
  File "/usr/lib/python3/dist-packages/urllib3/connection.py", line 314, in connect
    conn = self._new_conn()
  File "/usr/lib/python3/dist-packages/urllib3/connection.py", line 171, in _new_conn
    raise NewConnectionError(
urllib3.exceptions.NewConnectionError: <urllib3.connection.VerifiedHTTPSConnection object at 0x7f190e71daf0>: Failed to establish a new connection: [Errno -3] Temporary failure in name resolution

During handling of the above exception, another exception occurred:

Traceback (most recent call last):
  File "/usr/lib/python3/dist-packages/requests/adapters.py", line 439, in send
    resp = conn.urlopen(
  File "/usr/lib/python3/dist-packages/urllib3/connectionpool.py", line 719, in urlopen
    retries = retries.increment(
  File "/usr/lib/python3/dist-packages/urllib3/util/retry.py", line 436, in increment
    raise MaxRetryError(_pool, url, error or ResponseError(cause))
urllib3.exceptions.MaxRetryError: HTTPSConnectionPool(host='api.wandb.ai', port=443): Max retries exceeded with url: /graphql (Caused by NewConnectionError('<urllib3.connection.VerifiedHTTPSConnection object at 0x7f190e71daf0>: Failed to establish a new connection: [Errno -3] Temporary failure in name resolution'))

During handling of the above exception, another exception occurred:

Traceback (most recent call last):
  File "/home/atharva1511/.local/lib/python3.8/site-packages/wandb/sdk/lib/retry.py", line 102, in __call__
    result = self._call_fn(*args, **kwargs)
  File "/home/atharva1511/.local/lib/python3.8/site-packages/wandb/sdk/internal/internal_api.py", line 140, in execute
    return self.client.execute(*args, **kwargs)
  File "/home/atharva1511/.local/lib/python3.8/site-packages/wandb/vendor/gql-0.2.0/wandb_gql/client.py", line 52, in execute
    result = self._get_result(document, *args, **kwargs)
  File "/home/atharva1511/.local/lib/python3.8/site-packages/wandb/vendor/gql-0.2.0/wandb_gql/client.py", line 60, in _get_result
    return self.transport.execute(document, *args, **kwargs)
  File "/home/atharva1511/.local/lib/python3.8/site-packages/wandb/vendor/gql-0.2.0/wandb_gql/transport/requests.py", line 38, in execute
    request = requests.post(self.url, **post_args)
  File "/usr/lib/python3/dist-packages/requests/api.py", line 116, in post
    return request('post', url, data=data, json=json, **kwargs)
  File "/usr/lib/python3/dist-packages/requests/api.py", line 60, in request
    return session.request(method=method, url=url, **kwargs)
  File "/usr/lib/python3/dist-packages/requests/sessions.py", line 533, in request
    resp = self.send(prep, **send_kwargs)
  File "/usr/lib/python3/dist-packages/requests/sessions.py", line 646, in send
    r = adapter.send(request, **kwargs)
  File "/usr/lib/python3/dist-packages/requests/adapters.py", line 516, in send
    raise ConnectionError(e, request=request)
requests.exceptions.ConnectionError: HTTPSConnectionPool(host='api.wandb.ai', port=443): Max retries exceeded with url: /graphql (Caused by NewConnectionError('<urllib3.connection.VerifiedHTTPSConnection object at 0x7f190e71daf0>: Failed to establish a new connection: [Errno -3] Temporary failure in name resolution'))
2022-03-15 21:31:11,716 WARNING MainThread:10218 [internal.py:wandb_internal():155] Internal process interrupt: 1
2022-03-15 21:31:13,654 WARNING MainThread:10218 [internal.py:wandb_internal():155] Internal process interrupt: 2
2022-03-15 21:31:13,654 ERROR   MainThread:10218 [internal.py:wandb_internal():158] Internal process interrupted.
2022-03-15 21:31:14,395 INFO    WriterThread:10218 [datastore.py:close():281] close: /home/atharva1511/Downloads/CS6910/CS6910/code2/wandb/run-20220315_213042-3jrc9ezd/run-3jrc9ezd.wandb
2022-03-15 21:31:14,424 INFO    HandlerThread:10218 [handler.py:finish():778] shutting down handler
2022-03-15 21:35:23,486 INFO    SenderThread:10218 [dir_watcher.py:__init__():169] watching files in: /home/atharva1511/Downloads/CS6910/CS6910/code2/wandb/run-20220315_213042-3jrc9ezd/files
2022-03-15 21:35:23,487 INFO    SenderThread:10218 [sender.py:_start_run_threads():812] run started: 3jrc9ezd with start time 1647360042
2022-03-15 21:35:23,487 INFO    SenderThread:10218 [sender.py:finish():1078] shutting down sender
2022-03-15 21:35:23,487 INFO    SenderThread:10218 [dir_watcher.py:finish():283] shutting down directory watcher
2022-03-15 21:35:24,488 INFO    SenderThread:10218 [dir_watcher.py:finish():313] scan: /home/atharva1511/Downloads/CS6910/CS6910/code2/wandb/run-20220315_213042-3jrc9ezd/files
2022-03-15 21:35:24,488 INFO    SenderThread:10218 [dir_watcher.py:finish():327] scan save: /home/atharva1511/Downloads/CS6910/CS6910/code2/wandb/run-20220315_213042-3jrc9ezd/files/config.yaml config.yaml
2022-03-15 21:35:24,489 INFO    SenderThread:10218 [file_pusher.py:finish():145] shutting down file pusher
2022-03-15 21:35:24,489 INFO    SenderThread:10218 [file_pusher.py:join():150] waiting for file pusher
2022-03-15 21:35:25,503 INFO    Thread-9  :10218 [upload_job.py:push():137] Uploaded file /home/atharva1511/Downloads/CS6910/CS6910/code2/wandb/run-20220315_213042-3jrc9ezd/files/config.yaml
2022-03-15 21:35:26,368 INFO    MainThread:10218 [internal.py:handle_exit():82] Internal process exited
