Traceback (most recent call last):
  File "/home/atharva1511/.local/lib/python3.8/site-packages/pandas/core/indexes/base.py", line 3621, in get_loc
    return self._engine.get_loc(casted_key)
  File "pandas/_libs/index.pyx", line 136, in pandas._libs.index.IndexEngine.get_loc
  File "pandas/_libs/index.pyx", line 163, in pandas._libs.index.IndexEngine.get_loc
  File "pandas/_libs/hashtable_class_helper.pxi", line 5198, in pandas._libs.hashtable.PyObjectHashTable.get_item
  File "pandas/_libs/hashtable_class_helper.pxi", line 5206, in pandas._libs.hashtable.PyObjectHashTable.get_item
KeyError: 'y'
The above exception was the direct cause of the following exception:
Traceback (most recent call last):
  File "train.py", line 117, in <module>
    train_one_epoch(model, trainloader, optimizer,
  File "train.py", line 42, in train_one_epoch
    for i, (data, target) in enumerate(dataset):
  File "/home/atharva1511/.local/lib/python3.8/site-packages/torch/utils/data/dataloader.py", line 530, in __next__
    data = self._next_data()
  File "/home/atharva1511/.local/lib/python3.8/site-packages/torch/utils/data/dataloader.py", line 570, in _next_data
    data = self._dataset_fetcher.fetch(index)  # may raise StopIteration
  File "/home/atharva1511/.local/lib/python3.8/site-packages/torch/utils/data/_utils/fetch.py", line 49, in fetch
    data = [self.dataset[idx] for idx in possibly_batched_index]
  File "/home/atharva1511/.local/lib/python3.8/site-packages/torch/utils/data/_utils/fetch.py", line 49, in <listcomp>
    data = [self.dataset[idx] for idx in possibly_batched_index]
  File "/home/atharva1511/Downloads/CS6910/assignment2/code2/dataloader.py", line 31, in __getitem__
    output = self.y.loc[idx, 'y'].astype(np.float32)
  File "/home/atharva1511/.local/lib/python3.8/site-packages/pandas/core/indexing.py", line 960, in __getitem__
    return self.obj._get_value(*key, takeable=self._takeable)
  File "/home/atharva1511/.local/lib/python3.8/site-packages/pandas/core/frame.py", line 3615, in _get_value
    series = self._get_item_cache(col)
  File "/home/atharva1511/.local/lib/python3.8/site-packages/pandas/core/frame.py", line 3931, in _get_item_cache
    loc = self.columns.get_loc(item)
  File "/home/atharva1511/.local/lib/python3.8/site-packages/pandas/core/indexes/base.py", line 3623, in get_loc
    raise KeyError(key) from err
KeyError: 'y'
Traceback (most recent call last):
  File "/home/atharva1511/.local/lib/python3.8/site-packages/pandas/core/indexes/base.py", line 3621, in get_loc
    return self._engine.get_loc(casted_key)
  File "pandas/_libs/index.pyx", line 136, in pandas._libs.index.IndexEngine.get_loc
  File "pandas/_libs/index.pyx", line 163, in pandas._libs.index.IndexEngine.get_loc
  File "pandas/_libs/hashtable_class_helper.pxi", line 5198, in pandas._libs.hashtable.PyObjectHashTable.get_item
  File "pandas/_libs/hashtable_class_helper.pxi", line 5206, in pandas._libs.hashtable.PyObjectHashTable.get_item
KeyError: 'y'
The above exception was the direct cause of the following exception:
Traceback (most recent call last):
  File "train.py", line 117, in <module>
    train_one_epoch(model, trainloader, optimizer,
  File "train.py", line 42, in train_one_epoch
    for i, (data, target) in enumerate(dataset):
  File "/home/atharva1511/.local/lib/python3.8/site-packages/torch/utils/data/dataloader.py", line 530, in __next__
    data = self._next_data()
  File "/home/atharva1511/.local/lib/python3.8/site-packages/torch/utils/data/dataloader.py", line 570, in _next_data
    data = self._dataset_fetcher.fetch(index)  # may raise StopIteration
  File "/home/atharva1511/.local/lib/python3.8/site-packages/torch/utils/data/_utils/fetch.py", line 49, in fetch
    data = [self.dataset[idx] for idx in possibly_batched_index]
  File "/home/atharva1511/.local/lib/python3.8/site-packages/torch/utils/data/_utils/fetch.py", line 49, in <listcomp>
    data = [self.dataset[idx] for idx in possibly_batched_index]
  File "/home/atharva1511/Downloads/CS6910/assignment2/code2/dataloader.py", line 31, in __getitem__
    output = self.y.loc[idx, 'y'].astype(np.float32)
  File "/home/atharva1511/.local/lib/python3.8/site-packages/pandas/core/indexing.py", line 960, in __getitem__
    return self.obj._get_value(*key, takeable=self._takeable)
  File "/home/atharva1511/.local/lib/python3.8/site-packages/pandas/core/frame.py", line 3615, in _get_value
    series = self._get_item_cache(col)
  File "/home/atharva1511/.local/lib/python3.8/site-packages/pandas/core/frame.py", line 3931, in _get_item_cache
    loc = self.columns.get_loc(item)
  File "/home/atharva1511/.local/lib/python3.8/site-packages/pandas/core/indexes/base.py", line 3623, in get_loc
    raise KeyError(key) from err
KeyError: 'y'