2022-03-15 21:33:28,333 INFO    MainThread:10319 [wandb_setup.py:_flush():75] Loading settings from /home/atharva1511/.config/wandb/settings
2022-03-15 21:33:28,333 INFO    MainThread:10319 [wandb_setup.py:_flush():75] Loading settings from /home/atharva1511/Downloads/CS6910/CS6910/code2/wandb/settings
2022-03-15 21:33:28,333 INFO    MainThread:10319 [wandb_setup.py:_flush():75] Loading settings from environment variables: {}
2022-03-15 21:33:28,333 INFO    MainThread:10319 [wandb_setup.py:_flush():75] Inferring run settings from compute environment: {'program_relpath': 'Downloads/CS6910/CS6910/code2/train.py', 'program': 'train.py'}
2022-03-15 21:33:28,333 INFO    MainThread:10319 [wandb_init.py:_log_setup():405] Logging user logs to /home/atharva1511/Downloads/CS6910/CS6910/code2/wandb/run-20220315_213328-3s59t3un/logs/debug.log
2022-03-15 21:33:28,333 INFO    MainThread:10319 [wandb_init.py:_log_setup():406] Logging internal logs to /home/atharva1511/Downloads/CS6910/CS6910/code2/wandb/run-20220315_213328-3s59t3un/logs/debug-internal.log
2022-03-15 21:33:28,333 INFO    MainThread:10319 [wandb_init.py:init():439] calling init triggers
2022-03-15 21:33:28,333 INFO    MainThread:10319 [wandb_init.py:init():442] wandb.init called with sweep_config: {}
config: {'checkpoint_dir': 'models', 'train_file_path': '../20/task2a/train_t20.csv', 'val_file_path': '../20/task2a/dev_t20.csv', 'cuda': False, 'wandb': False, 'do_train': True, 'do_val': True, 'do_predict': True, 'use_trained': True, 'batch_size': 1, 'epochs': 1, 'val_batch_size': 1, 'output_num': 1, 'input_num': 2, 'num_hidden1': 13, 'num_hidden2': 18, 'learning_rate': 9.2e-05, 'momentum': 0.9198}
2022-03-15 21:33:28,333 INFO    MainThread:10319 [wandb_init.py:init():492] starting backend
2022-03-15 21:33:28,333 INFO    MainThread:10319 [backend.py:_multiprocessing_setup():99] multiprocessing start_methods=fork,spawn,forkserver, using: spawn
2022-03-15 21:33:28,337 INFO    MainThread:10319 [backend.py:ensure_launched():219] starting backend process...
2022-03-15 21:33:28,341 INFO    MainThread:10319 [backend.py:ensure_launched():224] started backend process with pid: 10335
2022-03-15 21:33:28,342 INFO    MainThread:10319 [wandb_init.py:init():501] backend started and connected
2022-03-15 21:33:28,344 INFO    MainThread:10319 [wandb_init.py:init():565] updated telemetry
2022-03-15 21:33:28,346 INFO    MainThread:10319 [wandb_init.py:init():596] communicating run to backend with 30 second timeout
2022-03-15 21:33:44,876 ERROR   Thread-1  :10319 [retry.py:__call__():126] Retry attempt failed:
Traceback (most recent call last):
  File "/usr/lib/python3/dist-packages/urllib3/connection.py", line 159, in _new_conn
    conn = connection.create_connection(
  File "/usr/lib/python3/dist-packages/urllib3/util/connection.py", line 61, in create_connection
    for res in socket.getaddrinfo(host, port, family, socket.SOCK_STREAM):
  File "/usr/lib/python3.8/socket.py", line 918, in getaddrinfo
    for res in _socket.getaddrinfo(host, port, family, type, proto, flags):
socket.gaierror: [Errno -2] Name or service not known

During handling of the above exception, another exception occurred:

Traceback (most recent call last):
  File "/usr/lib/python3/dist-packages/urllib3/connectionpool.py", line 665, in urlopen
    httplib_response = self._make_request(
  File "/usr/lib/python3/dist-packages/urllib3/connectionpool.py", line 376, in _make_request
    self._validate_conn(conn)
  File "/usr/lib/python3/dist-packages/urllib3/connectionpool.py", line 996, in _validate_conn
    conn.connect()
  File "/usr/lib/python3/dist-packages/urllib3/connection.py", line 314, in connect
    conn = self._new_conn()
  File "/usr/lib/python3/dist-packages/urllib3/connection.py", line 171, in _new_conn
    raise NewConnectionError(
urllib3.exceptions.NewConnectionError: <urllib3.connection.VerifiedHTTPSConnection object at 0x7ff70ecff0a0>: Failed to establish a new connection: [Errno -2] Name or service not known

During handling of the above exception, another exception occurred:

Traceback (most recent call last):
  File "/usr/lib/python3/dist-packages/requests/adapters.py", line 439, in send
    resp = conn.urlopen(
  File "/usr/lib/python3/dist-packages/urllib3/connectionpool.py", line 719, in urlopen
    retries = retries.increment(
  File "/usr/lib/python3/dist-packages/urllib3/util/retry.py", line 436, in increment
    raise MaxRetryError(_pool, url, error or ResponseError(cause))
urllib3.exceptions.MaxRetryError: HTTPSConnectionPool(host='api.wandb.ai', port=443): Max retries exceeded with url: /graphql (Caused by NewConnectionError('<urllib3.connection.VerifiedHTTPSConnection object at 0x7ff70ecff0a0>: Failed to establish a new connection: [Errno -2] Name or service not known'))

During handling of the above exception, another exception occurred:

Traceback (most recent call last):
  File "/home/atharva1511/.local/lib/python3.8/site-packages/wandb/sdk/lib/retry.py", line 102, in __call__
    result = self._call_fn(*args, **kwargs)
  File "/home/atharva1511/.local/lib/python3.8/site-packages/wandb/sdk/internal/internal_api.py", line 140, in execute
    return self.client.execute(*args, **kwargs)
  File "/home/atharva1511/.local/lib/python3.8/site-packages/wandb/vendor/gql-0.2.0/wandb_gql/client.py", line 52, in execute
    result = self._get_result(document, *args, **kwargs)
  File "/home/atharva1511/.local/lib/python3.8/site-packages/wandb/vendor/gql-0.2.0/wandb_gql/client.py", line 60, in _get_result
    return self.transport.execute(document, *args, **kwargs)
  File "/home/atharva1511/.local/lib/python3.8/site-packages/wandb/vendor/gql-0.2.0/wandb_gql/transport/requests.py", line 38, in execute
    request = requests.post(self.url, **post_args)
  File "/usr/lib/python3/dist-packages/requests/api.py", line 116, in post
    return request('post', url, data=data, json=json, **kwargs)
  File "/usr/lib/python3/dist-packages/requests/api.py", line 60, in request
    return session.request(method=method, url=url, **kwargs)
  File "/usr/lib/python3/dist-packages/requests/sessions.py", line 533, in request
    resp = self.send(prep, **send_kwargs)
  File "/usr/lib/python3/dist-packages/requests/sessions.py", line 646, in send
    r = adapter.send(request, **kwargs)
  File "/usr/lib/python3/dist-packages/requests/adapters.py", line 516, in send
    raise ConnectionError(e, request=request)
requests.exceptions.ConnectionError: HTTPSConnectionPool(host='api.wandb.ai', port=443): Max retries exceeded with url: /graphql (Caused by NewConnectionError('<urllib3.connection.VerifiedHTTPSConnection object at 0x7ff70ecff0a0>: Failed to establish a new connection: [Errno -2] Name or service not known'))
2022-03-15 21:33:58,347 INFO    MainThread:10319 [interface_shared.py:_communicate_run():322] couldn't get run from backend
2022-03-15 21:33:58,347 ERROR   MainThread:10319 [wandb_init.py:init():601] backend process timed out
2022-03-15 21:33:58,348 ERROR   MainThread:10319 [wandb_init.py:init():610] encountered error: Error communicating with wandb process
try: wandb.init(settings=wandb.Settings(start_method='fork'))
or:  wandb.init(settings=wandb.Settings(start_method='thread'))
For more info see: https://docs.wandb.ai/library/init#init-start-error
2022-03-15 21:34:05,894 WARNING MainThread:10319 [wandb_init.py:init():975] interrupted
Traceback (most recent call last):
  File "/home/atharva1511/.local/lib/python3.8/site-packages/wandb/sdk/wandb_init.py", line 954, in init
    run = wi.init()
  File "/home/atharva1511/.local/lib/python3.8/site-packages/wandb/sdk/wandb_init.py", line 614, in init
    backend.cleanup()
  File "/home/atharva1511/.local/lib/python3.8/site-packages/wandb/sdk/backend/backend.py", line 250, in cleanup
    self.wandb_process.join()
  File "/usr/lib/python3.8/multiprocessing/process.py", line 149, in join
    res = self._popen.wait(timeout)
  File "/usr/lib/python3.8/multiprocessing/popen_fork.py", line 47, in wait
    return self.poll(os.WNOHANG if timeout == 0.0 else 0)
  File "/usr/lib/python3.8/multiprocessing/popen_fork.py", line 27, in poll
    pid, sts = os.waitpid(self.pid, flag)
KeyboardInterrupt
