2022-04-02 11:39:18,086 INFO    MainThread:7067 [internal.py:wandb_internal():92] W&B internal server running at pid: 7067, started at: 2022-04-02 11:39:18.085787
2022-04-02 11:39:18,087 INFO    WriterThread:7067 [datastore.py:open_for_write():77] open: /home/atharva1511/Downloads/CS6910/assignment2/task2/wandb/run-20220402_113917-v4r6hul9/run-v4r6hul9.wandb
2022-04-02 11:39:18,088 DEBUG   SenderThread:7067 [sender.py:send():235] send: header
2022-04-02 11:39:18,088 DEBUG   SenderThread:7067 [sender.py:send():235] send: run
2022-04-02 11:39:47,577 DEBUG   HandlerThread:7067 [handler.py:handle_request():141] handle_request: shutdown
2022-04-02 11:39:47,577 INFO    HandlerThread:7067 [handler.py:finish():778] shutting down handler
2022-04-02 11:39:48,098 INFO    WriterThread:7067 [datastore.py:close():281] close: /home/atharva1511/Downloads/CS6910/assignment2/task2/wandb/run-20220402_113917-v4r6hul9/run-v4r6hul9.wandb
2022-04-02 11:39:51,716 ERROR   SenderThread:7067 [retry.py:__call__():126] Retry attempt failed:
Traceback (most recent call last):
  File "/usr/lib/python3/dist-packages/urllib3/connection.py", line 159, in _new_conn
    conn = connection.create_connection(
  File "/usr/lib/python3/dist-packages/urllib3/util/connection.py", line 84, in create_connection
    raise err
  File "/usr/lib/python3/dist-packages/urllib3/util/connection.py", line 74, in create_connection
    sock.connect(sa)
socket.timeout: timed out

During handling of the above exception, another exception occurred:

Traceback (most recent call last):
  File "/usr/lib/python3/dist-packages/urllib3/connectionpool.py", line 665, in urlopen
    httplib_response = self._make_request(
  File "/usr/lib/python3/dist-packages/urllib3/connectionpool.py", line 376, in _make_request
    self._validate_conn(conn)
  File "/usr/lib/python3/dist-packages/urllib3/connectionpool.py", line 996, in _validate_conn
    conn.connect()
  File "/usr/lib/python3/dist-packages/urllib3/connection.py", line 314, in connect
    conn = self._new_conn()
  File "/usr/lib/python3/dist-packages/urllib3/connection.py", line 164, in _new_conn
    raise ConnectTimeoutError(
urllib3.exceptions.ConnectTimeoutError: (<urllib3.connection.VerifiedHTTPSConnection object at 0x7efccff239d0>, 'Connection to api.wandb.ai timed out. (connect timeout=10)')

During handling of the above exception, another exception occurred:

Traceback (most recent call last):
  File "/usr/lib/python3/dist-packages/requests/adapters.py", line 439, in send
    resp = conn.urlopen(
  File "/usr/lib/python3/dist-packages/urllib3/connectionpool.py", line 719, in urlopen
    retries = retries.increment(
  File "/usr/lib/python3/dist-packages/urllib3/util/retry.py", line 436, in increment
    raise MaxRetryError(_pool, url, error or ResponseError(cause))
urllib3.exceptions.MaxRetryError: HTTPSConnectionPool(host='api.wandb.ai', port=443): Max retries exceeded with url: /graphql (Caused by ConnectTimeoutError(<urllib3.connection.VerifiedHTTPSConnection object at 0x7efccff239d0>, 'Connection to api.wandb.ai timed out. (connect timeout=10)'))

During handling of the above exception, another exception occurred:

Traceback (most recent call last):
  File "/home/atharva1511/.local/lib/python3.8/site-packages/wandb/sdk/lib/retry.py", line 102, in __call__
    result = self._call_fn(*args, **kwargs)
  File "/home/atharva1511/.local/lib/python3.8/site-packages/wandb/sdk/internal/internal_api.py", line 140, in execute
    return self.client.execute(*args, **kwargs)
  File "/home/atharva1511/.local/lib/python3.8/site-packages/wandb/vendor/gql-0.2.0/wandb_gql/client.py", line 52, in execute
    result = self._get_result(document, *args, **kwargs)
  File "/home/atharva1511/.local/lib/python3.8/site-packages/wandb/vendor/gql-0.2.0/wandb_gql/client.py", line 60, in _get_result
    return self.transport.execute(document, *args, **kwargs)
  File "/home/atharva1511/.local/lib/python3.8/site-packages/wandb/vendor/gql-0.2.0/wandb_gql/transport/requests.py", line 38, in execute
    request = requests.post(self.url, **post_args)
  File "/usr/lib/python3/dist-packages/requests/api.py", line 116, in post
    return request('post', url, data=data, json=json, **kwargs)
  File "/usr/lib/python3/dist-packages/requests/api.py", line 60, in request
    return session.request(method=method, url=url, **kwargs)
  File "/usr/lib/python3/dist-packages/requests/sessions.py", line 533, in request
    resp = self.send(prep, **send_kwargs)
  File "/usr/lib/python3/dist-packages/requests/sessions.py", line 646, in send
    r = adapter.send(request, **kwargs)
  File "/usr/lib/python3/dist-packages/requests/adapters.py", line 504, in send
    raise ConnectTimeout(e, request=request)
requests.exceptions.ConnectTimeout: HTTPSConnectionPool(host='api.wandb.ai', port=443): Max retries exceeded with url: /graphql (Caused by ConnectTimeoutError(<urllib3.connection.VerifiedHTTPSConnection object at 0x7efccff239d0>, 'Connection to api.wandb.ai timed out. (connect timeout=10)'))
2022-04-02 11:39:56,753 INFO    SenderThread:7067 [dir_watcher.py:__init__():169] watching files in: /home/atharva1511/Downloads/CS6910/assignment2/task2/wandb/run-20220402_113917-v4r6hul9/files
2022-04-02 11:39:56,753 INFO    SenderThread:7067 [sender.py:_start_run_threads():812] run started: v4r6hul9 with start time 1648879757
2022-04-02 11:39:56,753 INFO    SenderThread:7067 [sender.py:finish():1078] shutting down sender
2022-04-02 11:39:56,753 INFO    SenderThread:7067 [dir_watcher.py:finish():283] shutting down directory watcher
2022-04-02 11:39:57,754 INFO    SenderThread:7067 [dir_watcher.py:finish():313] scan: /home/atharva1511/Downloads/CS6910/assignment2/task2/wandb/run-20220402_113917-v4r6hul9/files
2022-04-02 11:39:57,754 INFO    SenderThread:7067 [dir_watcher.py:finish():327] scan save: /home/atharva1511/Downloads/CS6910/assignment2/task2/wandb/run-20220402_113917-v4r6hul9/files/config.yaml config.yaml
2022-04-02 11:39:57,755 INFO    SenderThread:7067 [file_pusher.py:finish():145] shutting down file pusher
2022-04-02 11:39:57,755 INFO    SenderThread:7067 [file_pusher.py:join():150] waiting for file pusher
2022-04-02 11:39:58,609 INFO    Thread-9  :7067 [upload_job.py:push():137] Uploaded file /home/atharva1511/Downloads/CS6910/assignment2/task2/wandb/run-20220402_113917-v4r6hul9/files/config.yaml
2022-04-02 11:39:59,559 INFO    MainThread:7067 [internal.py:handle_exit():82] Internal process exited
